Workbook

Sheet 1. Business Financials
B2: Financial Information Submission Form
B4: Instructions: Please provide the following financial information to enable the Innovate UK credit team to consider whether your business is suitable to take on an innovation loan. You must provide historic financial information for the last three years (or since incorporation if shorter) and forecast financial information for the full period of the proposed innovation loan. It is mandatory to complete this worksheet as part of your application. If you do not complete this template fully to show your actual and forecast financial position, your application will not be considered. Note: the cells highlighted in purple signify actual figures and those highlighted in blue are auto-populated (i.e. formula driven) so cannot be edited. The financial line items that relate to the innovation loan will be auto-populated based on the inputs in the '3. Repayment Calc Template' tab, as well as the loan start date and year end fields below. For details on how each line is calculated please refer to the '4. Innovation Loan Calcs' tab. You may wish to add additional tabs to this worksheet to provide supplementary information (e.g. on revenue / cost forecast assumptions, sales pipelines or sensitivities) where it maybe useful for our Credit analysis. This is optional, however, it is strongly advisable to at least complete the '2. Sales Assumptions' tab. **Once you have completed the input of your financial information to this spreadsheet, please save all tabs of the workbook for upload in the business and financial information section of your application.**
E16: Further guidance on use of this worksheet is available at: | J16: https://go.innovateuk.ukri.org/Loan_Finance_Guide
B17: Application number:
B18: Company name:
B19: Fiscal year end-date (dd/mm/yyyy): | C19: =Sheet1!D2&"/"&Sheet1!E2&"/"&'1. Business Financials'!C20 -> #N/A
B20: Year: | C20: =RIGHT(C21,4)+Sheet1!E3 -> #VALUE!
B21: Loan start date (dd/mm/yyyy):
B22: Year end:
B24: P&L / Balance Sheet Summary (annual)
C26: Actual | F26: Forecast
B27: Financial year | C27: =IFERROR("FY"&C20-3,"") | D27: =IFERROR("FY"&C20-2,"") | E27: =IFERROR("FY"&C20-1,"") | F27: =IFERROR("FY"&C20,"") | G27: =IFERROR("FY"&C20+1,"") | H27: =IFERROR("FY"&C20+2,"") | I27: =IFERROR("FY"&C20+3,"") | J27: =IFERROR("FY"&C20+4,"") | K27: =IFERROR("FY"&C20+5,"") | L27: =IFERROR("FY"&C20+6,"") | M27: =IFERROR("FY"&C20+7,"") | N27: =IFERROR("FY"&C20+8,"") | O27: =IFERROR("FY"&C20+9,"")
B28: Turnover | F28: ='2. Sales Assumptions'!G50 -> 0 | G28: ='2. Sales Assumptions'!G51 -> 0 | H28: ='2. Sales Assumptions'!G52 -> 0 | I28: ='2. Sales Assumptions'!G53 -> 0 | J28: ='2. Sales Assumptions'!G54 -> 0 | K28: ='2. Sales Assumptions'!G55 -> 0 | L28: ='2. Sales Assumptions'!G56 -> 0 | M28: ='2. Sales Assumptions'!G57 -> 0 | N28: ='2. Sales Assumptions'!G58 -> 0 | O28: ='2. Sales Assumptions'!G59 -> 0
B29: Other income / grants
B30: Total income | C30: =C28+C29 -> 0 | D30: =D28+D29 -> 0 | E30: =E28+E29 -> 0 | F30: =F28+F29 -> 0 | G30: =G28+G29 -> 0 | H30: =H28+H29 -> 0 | I30: =I28+I29 -> 0 | J30: =J28+J29 -> 0 | ... O30: =O28+O29 -> 0
B31: Cost of Sales | F31: ='2. Sales Assumptions'!G66 -> 0 | G31: ='2. Sales Assumptions'!G67 -> 0 | H31: ='2. Sales Assumptions'!G68 -> 0 | I31: ='2. Sales Assumptions'!G69 -> 0 | J31: ='2. Sales Assumptions'!G70 -> 0 | K31: ='2. Sales Assumptions'!G71 -> 0 | L31: ='2. Sales Assumptions'!G72 -> 0 | M31: ='2. Sales Assumptions'!G73 -> 0 | N31: ='2. Sales Assumptions'!G74 -> 0 | O31: ='2. Sales Assumptions'!G75 -> 0
B32: Gross Profit | C32: =C30-C31 -> 0 | D32: =D30-D31 -> 0 | E32: =E30-E31 -> 0 | F32: =F30-F31 -> 0 | G32: =G30-G31 -> 0 | H32: =H30-H31 -> 0 | I32: =I30-I31 -> 0 | J32: =J30-J31 -> 0 | ... O32: =O30-O31 -> 0
B33: Administrative and other costs
B34: EBITDA | C34: =C32-C33 -> 0 | D34: =D32-D33 -> 0 | E34: =E32-E33 -> 0 | F34: =F32-F33 -> 0 | G34: =G32-G33 -> 0 | H34: =H32-H33 -> 0 | I34: =I32-I33 -> 0 | J34: =J32-J33 -> 0 | ... O34: =O32-O33 -> 0
B35: Innovation Loan Interest | C35: 0 | D35: 0 | E35: 0 | F35: =IFERROR('4. Innovation Loans Calcs'!G13,0) -> 0 | G35: =IFERROR('4. Innovation Loans Calcs'!G14,0) -> 0 | H35: =IFERROR('4. Innovation Loans Calcs'!G15,0) -> 0 | I35: =IFERROR('4. Innovation Loans Calcs'!G16,0) -> 0 | J35: =IFERROR('4. Innovation Loans Calcs'!G17,0) -> 0 | K35: =IFERROR('4. Innovation Loans Calcs'!G18,0) -> 0 | L35: =IFERROR('4. Innovation Loans Calcs'!G19,0) -> 0 | M35: =IFERROR('4. Innovation Loans Calcs'!G20,0) -> 0 | N35: =IFERROR('4. Innovation Loans Calcs'!G21,0) -> 0 | O35: =IFERROR('4. Innovation Loans Calcs'!G22,0) -> 0
B36: Other Interest
B37: Depreciation / amortisation
B38: Tax
B39: Net profit | C39: =C34-C35-C36-C37-C38 -> 0 | D39: =D34-D35-D36-D37-D38 -> 0 | E39: =E34-E35-E36-E37-E38 -> 0 | F39: =F34-F35-F36-F37-F38 -> 0 | G39: =G34-G35-G36-G37-G38 -> 0 | H39: =H34-H35-H36-H37-H38 -> 0 | I39: =I34-I35-I36-I37-I38 -> 0 | J39: =J34-J35-J36-J37-J38 -> 0 | ... O39: =O34-O35-O36-O37-O38 -> 0
B41: Fixed assets (tangible & intangible)
B42: Cash
B43: Debtors
B44: Inventories
B45: Other current assets
B46: Total current assets | C46: =C42+C43+C44+C45 -> 0 | D46: =D42+D43+D44+D45 -> 0 | E46: =E42+E43+E44+E45 -> 0 | F46: =F42+F43+F44+F45 -> 0 | G46: =G42+G43+G44+G45 -> 0 | H46: =H42+H43+H44+H45 -> 0 | I46: =I42+I43+I44+I45 -> 0 | J46: =J42+J43+J44+J45 -> 0 | ... O46: =O42+O43+O44+O45 -> 0
B47: Total assets | C47: =C41+C46 -> 0 | D47: =D41+D46 -> 0 | E47: =E41+E46 -> 0 | F47: =F41+F46 -> 0 | G47: =G41+G46 -> 0 | H47: =H41+H46 -> 0 | I47: =I41+I46 -> 0 | J47: =J41+J46 -> 0 | ... O47: =O41+O46 -> 0
B48: Trade Creditors
B49: Bank loans / overdrafts repayable <1 year
B50: Other current liabilities
B51: Total current liabilities | C51: =C48+C49+C50 -> 0 | D51: =D48+D49+D50 -> 0 | E51: =E48+E49+E50 -> 0 | F51: =F48+F49+F50 -> 0 | G51: =G48+G49+G50 -> 0 | H51: =H48+H49+H50 -> 0 | I51: =I48+I49+I50 -> 0 | J51: =J48+J49+J50 -> 0 | ... O51: =O48+O49+O50 -> 0
B52: Bank loans repayable >1 year
B53: Directors loans
B54: Innovation Loan | F54: =IFERROR('4. Innovation Loans Calcs'!C13,0) -> 0 | G54: =IFERROR('4. Innovation Loans Calcs'!C14,0) -> 0 | H54: =IFERROR('4. Innovation Loans Calcs'!C15,0) -> 0 | I54: =IFERROR('4. Innovation Loans Calcs'!C16,0) -> 0 | J54: =IFERROR('4. Innovation Loans Calcs'!C17,0) -> 0 | K54: =IFERROR('4. Innovation Loans Calcs'!C18,0) -> 0 | L54: =IFERROR('4. Innovation Loans Calcs'!C19,0) -> 0 | M54: =IFERROR('4. Innovation Loans Calcs'!C20,0) -> 0 | N54: =IFERROR('4. Innovation Loans Calcs'!C21,0) -> 0 | O54: =IFERROR('4. Innovation Loans Calcs'!C22,0) -> 0
B55: Other long term liabilities
B56: Total liabilities | C56: =C51+C52+C53+C54+C55 -> 0 | D56: =D51+D52+D53+D54+D55 -> 0 | E56: =E51+E52+E53+E54+E55 -> 0 | F56: =F51+F52+F53+F54+F55 -> 0 | G56: =G51+G52+G53+G54+G55 -> 0 | H56: =H51+H52+H53+H54+H55 -> 0 | I56: =I51+I52+I53+I54+I55 -> 0 | J56: =J51+J52+J53+J54+J55 -> 0 | ... O56: =O51+O52+O53+O54+O55 -> 0
...

Sheet 2. Sales Assumptions
B2: Sales Assumptions
B4: Instructions: This sheet will help you work out your anticipated sales/ turnover and cost of sales for the full forecast period of the proposed innovation loan which is required in tab 1. It is not mandatory to complete this tab, however, is strongly advisable to do so as it will help the credit team better understand any assumptions you have made in your forecasting. If you have your own model, please feel free to add that in a separate tab instead of completing the below. Work through this template in the order it sets out, as each section corresponds to the one that follows. Please complete all boxes highlighted yellow. The remainder of the cells will then auto-populate.
B9: 1. Product breakdown
C11: Product / Service 1 | D11: Product / Service 2 | E11: Product / Service 3 | F11: Product / Service 4 | J11: Worked Example
B12: Product / Service name | C12: Test 1 | D12: Test 2 | J12: T-Shirts
B14: Cost of sales breakdown per unit/ subscription/ user | C14: =IF($C$12="","",$C$12) -> Test 1 | D14: =IF($D$12="","",$D$12) -> Test 2 | E14: =IF($E$12="","",$E$12) | F14: =IF($F$12="","",$F$12) | J14: Worked Example
B15: [Direct materials] | J15: 2.5
B16: [Direct labour] | J16: 5
B17: [Other subcontractors] | J17: 3
B18: [Other cost 1] | J18: 1.5
B19: [Other cost 2]
B20: [Other cost 3]
B21: [Other cost 4]
B22: Total cost (per unit/ subscription/ user) | C22: =SUM(C15:C21) -> 0 | D22: =SUM(D15:D21) -> 0 | E22: =SUM(E15:E21) -> 0 | F22: =SUM(F15:F21) -> 0 | J22: =SUM(J15:J21) -> 12
C24: =IF($C$12="","",$C$12) -> Test 1 | D24: =IF($D$12="","",$D$12) -> Test 2 | E24: =IF($E$12="","",$E$12) | F24: =IF($F$12="","",$F$12) | J24: Worked Example
B25: Sale price (per unit/ subscription/ user) | J25: 25
B26: Cost (per unit/ subscription/ user) | C26: =C22 -> 0 | D26: =D22 -> 0 | E26: =E22 -> 0 | F26: =F22 -> 0 | J26: =J22 -> 12
B27: Gross Margin (per unit/ subscription/ user) | C27: =IFERROR(SUM(C25-C26)/C25,"") | D27: =IFERROR(SUM(D25-D26)/D25,"") | E27: =IFERROR(SUM(E25-E26)/E25,"") | F27: =IFERROR(SUM(F25-F26)/F25,"") | J27: =SUM(J25-J26)/J25 -> 0.52
B29: 2. Number of sales per year
B30: In these cells, enter the quantity of sales that you expect to make for each item over the forecast period of the proposed innovation loan (i.e. the number of unit sales for products, the number of annual subscriptions/ users for services).
B33: Year | C33: =IF($C$12="","",$C$12) -> Test 1 | D33: =IF($D$12="","",$D$12) -> Test 2 | E33: =IF($E$12="","",$E$12) | F33: =IF($F$12="","",$F$12) | G33: Total sales volumes per year | H33: Average sales volumes per month* | J33: Worked Example
B34: ='1. Business Financials'!F27 | G34: =SUM(C34:F34) -> 0 | H34: =SUM(G34/12) -> 0 | J34: 30
B35: ='1. Business Financials'!G27 | G35: =SUM(C35:F35) -> 0 | H35: =SUM(G35/12) -> 0 | J35: 28
B36: ='1. Business Financials'!H27 | G36: =SUM(C36:F36) -> 0 | H36: =SUM(G36/12) -> 0 | J36: 30
B37: ='1. Business Financials'!I27 | G37: =SUM(C37:F37) -> 0 | H37: =SUM(G37/12) -> 0 | J37: 45
B38: ='1. Business Financials'!J27 | G38: =SUM(C38:F38) -> 0 | H38: =SUM(G38/12) -> 0 | J38: 44
B39: ='1. Business Financials'!K27 | G39: =SUM(C39:F39) -> 0 | H39: =SUM(G39/12) -> 0 | J39: 46
B40: ='1. Business Financials'!L27 | G40: =SUM(C40:F40) -> 0 | H40: =SUM(G40/12) -> 0 | J40: 50
B41: ='1. Business Financials'!M27 | G41: =SUM(C41:F41) -> 0 | H41: =SUM(G41/12) -> 0 | J41: 48
B42: ='1. Business Financials'!N27 | G42: =SUM(C42:F42) -> 0 | H42: =SUM(G42/12) -> 0 | J42: 51
B43: ='1. Business Financials'!O27 | G43: =SUM(C43:F43) -> 0 | H43: =SUM(G43/12) -> 0 | J43: 55
H44: *Average sales value per month 12 month calender year
B46: Turnover
B47: You do not need to edit this section; this will auto-calculate based on your responses above.
B49: Year | C49: =C33 -> Test 1 | D49: =D33 -> Test 2 | E49: =E33 | F49: =F33 | G49: Total sales value (£) per year | H49: Average sales value per month* | J49: Worked Example
B50: =B34 | C50: =IFERROR(SUM($C$25*C34),"") -> 0 | D50: =IFERROR(SUM($D$25*D34),"") -> 0 | E50: =IFERROR(SUM($E$25*E34),"") -> 0 | F50: =IFERROR(SUM($F$25*F34),"") -> 0 | G50: =SUM(C50:F50) -> 0 | H50: =SUM(G50/12) -> 0 | J50: =SUM($J$25*J34) -> 750
B51: =B35 | C51: =IFERROR(SUM($C$25*C35),"") -> 0 | D51: =IFERROR(SUM($D$25*D35),"") -> 0 | E51: =IFERROR(SUM($E$25*E35),"") -> 0 | F51: =IFERROR(SUM($F$25*F35),"") -> 0 | G51: =SUM(C51:F51) -> 0 | H51: =SUM(G51/12) -> 0 | J51: =SUM($J$25*J35) -> 700
B52: =B36 | C52: =IFERROR(SUM($C$25*C36),"") -> 0 | D52: =IFERROR(SUM($D$25*D36),"") -> 0 | E52: =IFERROR(SUM($E$25*E36),"") -> 0 | F52: =IFERROR(SUM($F$25*F36),"") -> 0 | G52: =SUM(C52:F52) -> 0 | H52: =SUM(G52/12) -> 0 | J52: =SUM($J$25*J36) -> 750
B53: =B37 | C53: =IFERROR(SUM($C$25*C37),"") -> 0 | D53: =IFERROR(SUM($D$25*D37),"") -> 0 | E53: =IFERROR(SUM($E$25*E37),"") -> 0 | F53: =IFERROR(SUM($F$25*F37),"") -> 0 | G53: =SUM(C53:F53) -> 0 | H53: =SUM(G53/12) -> 0 | J53: =SUM($J$25*J37) -> 1125
B54: =B38 | C54: =IFERROR(SUM($C$25*C38),"") -> 0 | D54: =IFERROR(SUM($D$25*D38),"") -> 0 | E54: =IFERROR(SUM($E$25*E38),"") -> 0 | F54: =IFERROR(SUM($F$25*F38),"") -> 0 | G54: =SUM(C54:F54) -> 0 | H54: =SUM(G54/12) -> 0 | J54: =SUM($J$25*J38) -> 1100
...

Sheet 3. Repayment Calc Template
B2: Repayment Calculator Template
B4: Instructions: This sheet is a tool to help you calculate loan repayments and will drive the innovation loan amounts in tab 1. It is mandatory to complete this worksheet as part of your application. If you do not complete this template to show your innovation loan request, your application will not be considered. Please complete all boxes highlighted yellow. This will then populate the Availabilityn, Extensionn and Repaymentn tables below.
B7: Innovation Loan Request
B9: Eligible Project Costs
B10: Loan Amount | F10: Anticipated Drawdowns | I10: Anticipated Principal Outstanding | L10: Fees | AD10: 1 | AE10: 3 Months
C11: Quarters | D11: Years | F11: Quarter 1 | I11: Quarter 1 | J11: =G11 -> 0 | L11: Arrangement | M11: 0 | AD11: 2 | AE11: 6 Months
B12: Availability Period | D12: =IFERROR(VLOOKUP(C12,AD:AE,2,FALSE),"") | F12: Quarter 2 | I12: Quarter 2 | J12: =+J11+G12 -> 0 | L12: Monitoring | M12: 0 | AD12: 3 | AE12: 9 Months
B13: Extension Period | D13: =IFERROR(VLOOKUP(C13,AD:AE,2,FALSE),"") | F13: Quarter 3 | I13: Quarter 3 | J13: =+J12+G13 -> 0 | L13: Interest | AD13: 4 | AE13: 1 Year
B14: Repayment Period | D14: =IFERROR(VLOOKUP(C14,AD:AE,2,FALSE),"") | F14: Quarter 4 | I14: Quarter 4 | J14: =+J13+G14 -> 0 | L14: Reference | M14: 0.1424 | N14: Assuming B- rating | AD14: 5 | AE14: 15 Months
B15: No. of repayment quarters | C15: =C14 -> 0 | D15: =IF(SUM(C12:C14)>28,"Total loan term exceeds 7 years","") | F15: Quarter 5 | I15: Quarter 5 | J15: =+J14+G15 -> 0 | L15: Actual | M15: =M16+M17 -> 0.074 | AD15: 6 | AE15: 18 Months
F16: Quarter 6 | I16: Quarter 6 | J16: =+J15+G16 -> 0 | L16: Current | M16: 0.037
F17: Quarter 7 | I17: Quarter 7 | J17: =+J16+G17 -> 0 | L17: Deferred | M17: 0.037 | AD17: 7 | AE17: 21 Months
B18: Interest rate | C18: Qtly cash% | D18: Qtly deferred % | F18: Quarter 8 | I18: Quarter 8 | J18: =+J17+G18 -> 0 | AD18: 8 | AE18: 2 Years
B19: Availabilty Period | C19: =(M16*91.25/365) -> 0.00925 | D19: =(M17*91.25/365) -> 0.00925 | F19: Quarter 9 | I19: Quarter 9 | J19: =+J18+G19 -> 0 | AD19: 9 | AE19: 27 Months
B20: Extension Period | C20: =(M16*91.25/365) -> 0.00925 | D20: =(M17*91.25/365) -> 0.00925 | F20: Quarter 10 | I20: Quarter 10 | J20: =+J19+G20 -> 0 | AD20: 10 | AE20: 2.5 Years
B21: Repayment Period | C21: =($M$15*91.25/365) -> 0.0185 | D21: 0 | F21: Quarter 11 | I21: Quarter 11 | J21: =+J20+G21 -> 0 | AD21: 11 | AE21: 33 Months
F22: Quarter 12 | I22: Quarter 12 | J22: =+J21+G22 -> 0 | AD22: 12 | AE22: 3 Years
B23: Total Interest (A & E & R periods) | C23: =SUM(C50:J50)+SUM(C41:N41)+SUM(C57:V57) -> 0 | AD23: 13 | AE23: 39 Months
B24: Interest paid (A & E periods) | C24: =SUM(C47:J47)+SUM(C38:N38) -> 0 | AD24: 14 | AE24: 3.5 Years
B25: Deferred interest (A & E periods) | C25: =SUM(C48:J48)+SUM(C39:N39) -> 0 | AD25: 15 | AE25: 45 Months
B26: Interest paid (R period) | C26: =SUM(C57:V57) -> 0
B27: Fees paid | C27: =SUM(C40:N40)+SUM(C49:J49)+SUM(C58:V58) -> 0
B28: Total Principal | C28: =SUM(G11:G22) -> 0
B29: Total amount borrowed | C29: =SUM(G11:G22)+C25 -> 0
B30: Total payments (principal/interest/fees) | C30: =SUM(C59:V59)+SUM(C47:J47)+SUM(C38:N38) -> 0
B31: Quarterly Payment (excl fees) | C31: =IFERROR(-PMT(M15*91.25/365,C14,C29,0),0) -> 0 | D31: =C31*C14 -> 0
B33: Availability, Extension and Repayment Profiles
AD34: 16 | AE34: 4 Years
B35: Availability Period | AD35: 17 | AE35: 51 Months
C36: Quarter 1 | D36: Quarter 2 | E36: Quarter 3 | F36: Quarter 4 | G36: Quarter 5 | H36: Quarter 6 | I36: Quarter 7 | J36: Quarter 8 | K36: Quarter 9 | L36: Quarter 10 | M36: Quarter 11 | N36: Quarter 12 | AD36: 18 | AE36: 4.5 Years
C37: 1 | D37: =IF(C37=0,0,IF($C$12>C37,C37+1,0)) -> 0 | E37: =IF(D37=0,0,IF($C$12>D37,D37+1,0)) -> 0 | F37: =IF(E37=0,0,IF($C$12>E37,E37+1,0)) -> 0 | G37: =IF(F37=0,0,IF($C$12>F37,F37+1,0)) -> 0 | H37: =IF(G37=0,0,IF($C$12>G37,G37+1,0)) -> 0 | I37: =IF(H37=0,0,IF($C$12>H37,H37+1,0)) -> 0 | J37: =IF(I37=0,0,IF($C$12>I37,I37+1,0)) -> 0 | K37: =IF(J37=0,0,IF($C$12>J37,J37+1,0)) -> 0 | ... N37: =IF(M37=0,0,IF($C$12>M37,M37+1,0)) -> 0
B38: Interest paid (A period) | C38: =IF($C12>=1,$G11*$C19,0) -> 0 | D38: =IF($C12>=2,SUM($G11:$G12)*$C19,0) -> 0 | E38: =IF($C12>=3,SUM($G11:$G13)*$C19,0) -> 0 | F38: =IF($C12>=4,SUM($G11:$G14)*$C19,0) -> 0 | G38: =IF($C12>=5,SUM($G11:$G15)*$C19,0) -> 0 | H38: =IF($C12>=6,SUM($G11:$G16)*$C19,0) -> 0 | I38: =IF($C12>=7,SUM($G11:$G17)*$C19,0) -> 0 | J38: =IF($C12>=8,SUM($G11:$G18)*$C19,0) -> 0 | K38: =IF($C12>=9,SUM($G11:$G19)*$C19,0) -> 0 | L38: =IF($C12>=10,SUM($G11:$G20)*$C19,0) -> 0 | M38: =IF($C12>=11,SUM($G11:$G21)*$C19,0) -> 0 | N38: =IF($C12>=12,SUM($G11:$G22)*$C19,0) -> 0 | AD38: 19 | AE38: 57 Months
B39: Deferred interest | C39: =IF($C12>=1,$G11*$D19,0) -> 0 | D39: =IF($C12>=2,SUM($G11:$G12)*$D19,0) -> 0 | E39: =IF($C12>=3,SUM($G11:$G13)*$D19,0) -> 0 | F39: =IF($C12>=4,SUM($G11:$G14)*$D19,0) -> 0 | G39: =IF($C12>=5,SUM($G11:$G15)*$D19,0) -> 0 | H39: =IF($C12>=6,SUM($G11:$G16)*$D19,0) -> 0 | I39: =IF($C12>=7,SUM($G11:$G17)*$D19,0) -> 0 | J39: =IF($C12>=8,SUM($G11:$G18)*$D19,0) -> 0 | K39: =IF($C12>=9,SUM($G11:$G19)*$D19,0) -> 0 | L39: =IF($C12>=10,SUM($G11:$G20)*$D19,0) -> 0 | M39: =IF($C12>=11,SUM($G11:$G21)*$D19,0) -> 0 | N39: =IF($C12>=12,SUM($G11:$G22)*$D19,0) -> 0 | AD39: 20 | AE39: 5 Years
B40: Fees | C40: =IF($C12>=1,((C10*M11)+($J11*$M12/4)),0) -> 0 | D40: =IF($C12>=2,(($J12*$M12/4)),0) -> 0 | E40: =IF($C12>=3,(($J13*$M12/4)),0) -> 0 | F40: =IF($C12>=4,(($J14*$M12/4)),0) -> 0 | G40: =IF($C12>=5,(($J15*$M12/4)),0) -> 0 | H40: =IF($C12>=6,(($J16*$M12/4)),0) -> 0 | I40: =IF($C12>=7,(($J17*$M12/4)),0) -> 0 | J40: =IF($C12>=8,(($J18*$M12/4)),0) -> 0 | K40: =IF($C12>=9,(($J19*$M12/4)),0) -> 0 | L40: =IF($C12>=10,(($J20*$M12/4)),0) -> 0 | M40: =IF($C12>=11,(($J21*$M12/4)),0) -> 0 | N40: =IF($C12>=12,(($J22*$M12/4)),0) -> 0
B41: Total | C41: =SUM(C38:C40) -> 0 | D41: =SUM(D38:D40) -> 0 | E41: =SUM(E38:E40) -> 0 | F41: =SUM(F38:F40) -> 0 | G41: =SUM(G38:G40) -> 0 | H41: =SUM(H38:H40) -> 0 | I41: =SUM(I38:I40) -> 0 | J41: =SUM(J38:J40) -> 0 | ... N41: =SUM(N38:N40) -> 0
B44: Extension Period
C45: Quarter 1 | D45: Quarter 2 | E45: Quarter 3 | F45: Quarter 4 | G45: Quarter 5 | H45: Quarter 6 | I45: Quarter 7 | J45: Quarter 8
C46: =IF(C13=0,0,MAX(C37:N37)+1) -> 0 | D46: =IF(C46=0,0,IF(($C$12+$C$13)>C46,C46+1,0)) -> 0 | E46: =IF(D46=0,0,IF(($C$12+$C$13)>D46,D46+1,0)) -> 0 | F46: =IF(E46=0,0,IF(($C$12+$C$13)>E46,E46+1,0)) -> 0 | G46: =IF(F46=0,0,IF(($C$12+$C$13)>F46,F46+1,0)) -> 0 | H46: =IF(G46=0,0,IF(($C$12+$C$13)>G46,G46+1,0)) -> 0 | I46: =IF(H46=0,0,IF(($C$12+$C$13)>H46,H46+1,0)) -> 0 | J46: =IF(I46=0,0,IF(($C$12+$C$13)>I46,I46+1,0)) -> 0
B47: Interest paid (E period) | C47: =IF($C13>=1,SUM($G11:$G23)*$C20,0) -> 0 | D47: =IF($C13>=2,SUM($G11:$G23)*$C20,0) -> 0 | E47: =IF($C13>=3,SUM($G11:$G23)*$C20,0) -> 0 | F47: =IF($C13>=4,SUM($G11:$G23)*$C20,0) -> 0 | G47: =IF($C13>=5,SUM($G11:$G23)*$C20,0) -> 0 | H47: =IF($C13>=6,SUM($G11:$G23)*$C20,0) -> 0 | I47: =IF($C13>=7,SUM($G11:$G23)*$C20,0) -> 0 | J47: =IF($C13>=8,SUM($G11:$G23)*$C20,0) -> 0
B48: Deferred interest | C48: =IF($C13>=1,SUM($G11:$G23)*$D20,0) -> 0 | D48: =IF($C13>=2,SUM($G11:$G23)*$D20,0) -> 0 | E48: =IF($C13>=3,SUM($G11:$G23)*$D20,0) -> 0 | F48: =IF($C13>=4,SUM($G11:$G23)*$D20,0) -> 0 | G48: =IF($C13>=5,SUM($G11:$G23)*$D20,0) -> 0 | H48: =IF($C13>=6,SUM($G11:$G23)*$D20,0) -> 0 | I48: =IF($C13>=7,SUM($G11:$G23)*$D20,0) -> 0 | J48: =IF($C13>=8,SUM($G11:$G23)*$D20,0) -> 0
...

Sheet 4. Innovation Loans Calcs
B2: Innovation Loan Calculations
B4: Instructions: This tab is auto-populated and cannot be edited. It has been included to help you understand how the loan obligation items in the '1. Business Financials' have been calculated. The tables below calculate the loan drawdowns, accumulated interest, interest payments and capital payments per financial year across the loan life cycle based on the numbers provided in '3. Repayment Calc Template'. The workings within match the loan quarters to your financial years by calculating the number of months offset between the loan start date (selected in '1. Business Financials' tab) and your year-end (selected in '1. Business Financials' tab).
B9: The table below calculates the loan obligations per financial year based on the loan exposure per financial quarter (rows 30 to 34) and the proposed loan structure and amount (summarised in the quarters table below). | I9: This months off-set table defines the loan exposure per financial quarter based on the number of months offset between the loan start date and financial year end date.
B12: Financial Years | C12: Loan & Deferred Interest Outstanding | D12: Interest Paid | E12: Capital & Deferred Interest Repayments | F12: Drawdowns | G12: Interest P&L | I12: Months off-set | J12: 1 | K12: 2 | L12: 3 | M12: 4
B13: ='1. Business Financials'!F27 | C13: =IFERROR((C47*$C$32+D47*$C$33+E47*$C$34+F47*$C$35+C49*$C$32+D49*$C$33+E49*$C$34+F49*$C$35)-(C53*$C$32+$C$33*D53+E53*$C$34+$C$35*F53),0) -> 0 | D13: =SUM(C48,C52)*$C$32+SUM(D48,D52)*$C$33+SUM(E48,E52)*$C$34+SUM(F48,F52)*$C$35 -> 0 | E13: =(C53*$C$32+$C$33*D53+E53*$C$34+$C$35*F53) -> 0 | F13: =(C47*$C$32+D47*$C$33+E47*$C$34+F47*$C$35) -> 0 | G13: =SUM(C48,C49,C52)*$C$32+SUM(D48,D49,D52)*$C$33+SUM(E48,E49,E52)*$C$34+SUM(F48,F49,F52)*$C$35 -> 0 | I13: 0 | J13: 1 | K13: 1 | L13: 1 | M13: 1
B14: ='1. Business Financials'!G27 | C14: =IFERROR((C13+(1-$C$32)*C47+(1-$C$33)*D47+(1-$C$34)*E47+(1-$C$35)*F47+$C$32*G47+$C$33*H47+$C$34*I47+$C$35*J47+(1-$C$32)*C49+(1-$C$33)*D49+(1-$C$34)*E49+(1-$C$35)*F49+$C$32*G49+$C$33*H49+$C$34*I49+$C$35*J49)-((1-$C$32)*C53+(1-$C$33)*D53+(1-$C$34)*E53+(1-$C$35)*F53+$C$32*G53+$C$33*H53+$C$34*I53+$C$35*J53),0) -> 0 | D14: =SUM(C48,C52)*(1-$C$32)+SUM(D48,D52)*(1-$C$33)+SUM(E48,E52)*(1-$C$34)+SUM(F48,F52)*(1-$C$35)+SUM(G48,G52)*$C$32+SUM(H48,H52)*$C$33+SUM(I48,I52)*$C$34+SUM(J48,J52)*$C$35 -> 0 | E14: =(1-$C$32)*C53+(1-$C$33)*D53+(1-$C$34)*E53+(1-$C$35)*F53+$C$32*G53+$C$33*H53+$C$34*I53+$C$35*J53 -> 0 | F14: =(1-$C$32)*C47+(1-$C$33)*D47+(1-$C$34)*E47+(1-$C$35)*F47+$C$32*G47+$C$33*H47+$C$34*I47+$C$35*J47 -> 0 | G14: =SUM(C48,C49,C52)*(1-$C$32)+SUM(D48,D49,D52)*(1-$C$33)+SUM(E48,E49,E52)*(1-$C$34)+SUM(F48,F49,F52)*(1-$C$35)+SUM(G48,G49,G52)*$C$32+SUM(H48,H49,H52)*$C$33+SUM(I48,I49,I52)*$C$34+SUM(J48,J49,J52)*$C$35 -> 0 | I14: 1 | J14: 0.33 | K14: 0 | L14: 0 | M14: 0
B15: ='1. Business Financials'!H27 | C15: =IFERROR((C14+(1-$C$32)*G47+(1-$C$33)*H47+(1-$C$34)*I47+(1-$C$35)*J47+$C$32*K47+$C$33*L47+$C$34*M47+$C$35*N47+(1-$C$32)*G49+(1-$C$33)*H49+(1-$C$34)*I49+(1-$C$35)*J49+$C$32*K49+$C$33*L49+$C$34*M49+$C$35*N49)-((1-$C$32)*G53+(1-$C$33)*H53+(1-$C$34)*I53+(1-$C$35)*J53+$C$32*K53+$C$33*L53+$C$34*M53+$C$35*N53),0) -> 0 | D15: =SUM(G48,G52)*(1-$C$32)+SUM(H48,H52)*(1-$C$33)+SUM(I48,I52)*(1-$C$34)+SUM(J48,J52)*(1-$C$35)+SUM(K48,K52)*$C$32+SUM(L48,L52)*$C$33+SUM(M48,M52)*$C$34+SUM(N48,N52)*$C$35 -> 0 | E15: =(1-$C$32)*G53+(1-$C$33)*H53+(1-$C$34)*I53+(1-$C$35)*J53+$C$32*K53+$C$33*L53+$C$34*M53+$C$35*N53 -> 0 | F15: =(1-$C$32)*G47+(1-$C$33)*H47+(1-$C$34)*I47+(1-$C$35)*J47+$C$32*K47+$C$33*L47+$C$34*M47+$C$35*N47 -> 0 | G15: =SUM(G48,G49,G52)*(1-$C$32)+SUM(H48,H49,H52)*(1-$C$33)+SUM(I48,I49,I52)*(1-$C$34)+SUM(J48,J49,J52)*(1-$C$35)+SUM(K48,K49,K52)*$C$32+SUM(L48,L49,L52)*$C$33+SUM(M48,M49,M52)*$C$34+SUM(N48,N49,N52)*$C$35 -> 0 | I15: 2 | J15: 0.67 | K15: 0 | L15: 0 | M15: 0
B16: ='1. Business Financials'!I27 | C16: =IFERROR((C15+(1-$C$32)*K47+(1-$C$33)*L47+(1-$C$34)*M47+(1-$C$35)*N47+$C$32*O47+$C$33*P47+$C$34*Q47+$C$35*R47+(1-$C$32)*K49+(1-$C$33)*L49+(1-$C$34)*M49+(1-$C$35)*N49+$C$32*O49+$C$33*P49+$C$34*Q49+$C$35*R49)-((1-$C$32)*K53+(1-$C$33)*L53+(1-$C$34)*M53+(1-$C$35)*N53+$C$32*O53+$C$33*P53+$C$34*Q53+$C$35*R53),0) -> 0 | D16: =SUM(K48,K52)*(1-$C$32)+SUM(L48,L52)*(1-$C$33)+SUM(M48,M52)*(1-$C$34)+SUM(N48,N52)*(1-$C$35)+SUM(O48,O52)*$C$32+SUM(P48,P52)*$C$33+SUM(Q48,Q52)*$C$34+SUM(R48,R52)*$C$35 -> 0 | E16: =(1-$C$32)*K53+(1-$C$33)*L53+(1-$C$34)*M53+(1-$C$35)*N53+$C$32*O53+$C$33*P53+$C$34*Q53+$C$35*R53 -> 0 | F16: =(1-$C$32)*K47+(1-$C$33)*L47+(1-$C$34)*M47+(1-$C$35)*N47+$C$32*O47+$C$33*P47+$C$34*Q47+$C$35*R47 -> 0 | G16: =SUM(K48,K49,K52)*(1-$C$32)+SUM(L48,L49,L52)*(1-$C$33)+SUM(M48,M49,M52)*(1-$C$34)+SUM(N48,N49,N52)*(1-$C$35)+SUM(O48,O49,O52)*$C$32+SUM(P48,P49,P52)*$C$33+SUM(Q48,Q49,Q52)*$C$34+SUM(R48,R49,R52)*$C$35 -> 0 | I16: 3 | J16: 1 | K16: 0 | L16: 0 | M16: 0
B17: ='1. Business Financials'!J27 | C17: =IFERROR((C16+(1-$C$32)*O47+(1-$C$33)*P47+(1-$C$34)*Q47+(1-$C$35)*R47+$C$32*S47+$C$33*T47+$C$34*U47+$C$35*V47+(1-$C$32)*O49+(1-$C$33)*P49+(1-$C$34)*Q49+(1-$C$35)*R49+$C$32*S49+$C$33*T49+$C$34*U49+$C$35*V49)-((1-$C$32)*O53+(1-$C$33)*P53+(1-$C$34)*Q53+(1-$C$35)*R53+$C$32*S53+$C$33*T53+$C$34*U53+$C$35*V53),0) -> 0 | D17: =SUM(O48,O52)*(1-$C$32)+SUM(P48,P52)*(1-$C$33)+SUM(Q48,Q52)*(1-$C$34)+SUM(R48,R52)*(1-$C$35)+SUM(S48,S52)*$C$32+SUM(T48,T52)*$C$33+SUM(U48,U52)*$C$34+SUM(V48,V52)*$C$35 -> 0 | E17: =(1-$C$32)*O53+(1-$C$33)*P53+(1-$C$34)*Q53+(1-$C$35)*R53+$C$32*S53+$C$33*T53+$C$34*U53+$C$35*V53 -> 0 | F17: =(1-$C$32)*O47+(1-$C$33)*P47+(1-$C$34)*Q47+(1-$C$35)*R47+$C$32*S47+$C$33*T47+$C$34*U47+$C$35*V47 -> 0 | G17: =SUM(O48,O49,O52)*(1-$C$32)+SUM(P48,P49,P52)*(1-$C$33)+SUM(Q48,Q49,Q52)*(1-$C$34)+SUM(R48,R49,R52)*(1-$C$35)+SUM(S48,S49,S52)*$C$32+SUM(T48,T49,T52)*$C$33+SUM(U48,U49,U52)*$C$34+SUM(V48,V49,V52)*$C$35 -> 0 | I17: 4 | J17: 1 | K17: 0.33 | L17: 0 | M17: 0
B18: ='1. Business Financials'!K27 | C18: =IFERROR((C17+(1-$C$32)*S47+(1-$C$33)*T47+(1-$C$34)*U47+(1-$C$35)*V47+$C$32*W47+$C$33*X47+$C$34*Y47+$C$35*Z47)-((1-$C$32)*S53+(1-$C$33)*T53+(1-$C$34)*U53+(1-$C$35)*V53+$C$32*W53+$C$33*X53+$C$34*Y53+$C$35*Z53),0) -> 0 | D18: =SUM(S48,S52)*(1-$C$32)+SUM(T48,T52)*(1-$C$33)+SUM(U48,U52)*(1-$C$34)+SUM(V48,V52)*(1-$C$35)+SUM(W48,W52)*$C$32+SUM(X48,X52)*$C$33+SUM(Y48,Y52)*$C$34+SUM(Z48,Z52)*$C$35 -> 0 | E18: =(1-$C$32)*S53+(1-$C$33)*T53+(1-$C$34)*U53+(1-$C$35)*V53+$C$32*W53+$C$33*X53+$C$34*Y53+$C$35*Z53 -> 0 | F18: =(1-$C$32)*S47+(1-$C$33)*T47+(1-$C$34)*U47+(1-$C$35)*V47+$C$32*W47+$C$33*X47+$C$34*Y47+$C$35*Z47 -> 0 | G18: =SUM(S48,S49,S52)*(1-$C$32)+SUM(T48,T49,T52)*(1-$C$33)+SUM(U48,U49,U52)*(1-$C$34)+SUM(V48,V49,V52)*(1-$C$35)+SUM(W48,W49,W52)*$C$32+SUM(X48,X49,X52)*$C$33+SUM(Y48,Y49,Y52)*$C$34+SUM(Z48,Z49,Z52)*$C$35 -> 0 | I18: 5 | J18: 1 | K18: 0.67 | L18: 0 | M18: 0
B19: ='1. Business Financials'!L27 | C19: =IFERROR((C18+(1-$C$32)*W47+(1-$C$33)*X47+(1-$C$34)*Y47+(1-$C$35)*Z47+$C$32*AA47+$C$33*AB47+$C$34*AC47+$C$35*AD47+(1-$C$32)*W49+(1-$C$33)*X49+(1-$C$34)*Y49+(1-$C$35)*Z49+$C$32*AA49+$C$33*AB49+$C$34*AC49+$C$35*AD49)-((1-$C$32)*W53+(1-$C$33)*X53+(1-$C$34)*Y53+(1-$C$35)*Z53+$C$32*AA53+$C$33*AB53+$C$34*AC53+$C$35*AD53),0) -> 0 | D19: =SUM(W48,W52)*(1-$C$32)+SUM(X48,X52)*(1-$C$33)+SUM(Y48,Y52)*(1-$C$34)+SUM(Z48,Z52)*(1-$C$35)+SUM(AA48,AA52)*$C$32+SUM(AB48,AB52)*$C$33+SUM(AC48,AC52)*$C$34+SUM(AD48,AD52)*$C$35 -> 0 | E19: =(1-$C$32)*W53+(1-$C$33)*X53+(1-$C$34)*Y53+(1-$C$35)*Z53+$C$32*AA53+$C$33*AB53+$C$34*AC53+$C$35*AD53 -> 0 | F19: =(1-$C$32)*W47+(1-$C$33)*X47+(1-$C$34)*Y47+(1-$C$35)*Z47+$C$32*AA47+$C$33*AB47+$C$34*AC47+$C$35*AD47 -> 0 | G19: =SUM(W48,W49,W52)*(1-$C$32)+SUM(X48,X49,X52)*(1-$C$33)+SUM(Y48,Y49,Y52)*(1-$C$34)+SUM(Z48,Z49,Z52)*(1-$C$35)+SUM(AA48,AA49,AA52)*$C$32+SUM(AB48,AB49,AB52)*$C$33+SUM(AC48,AC49,AC52)*$C$34+SUM(AD48,AD49,AD52)*$C$35 -> 0 | I19: 6 | J19: 1 | K19: 1 | L19: 0 | M19: 0
B20: ='1. Business Financials'!M27 | C20: =IFERROR((C19+(1-$C$32)*AA47+(1-$C$33)*AB47+(1-$C$34)*AC47+(1-$C$35)*AD47+$C$32*AE47+$C$33*AF47+$C$34*AG47+$C$35*AH47+(1-$C$32)*AA49+(1-$C$33)*AB49+(1-$C$34)*AC49+(1-$C$35)*AD49+$C$32*AE49+$C$33*AF49+$C$34*AG49+$C$35*AH49)-((1-$C$32)*AA53+(1-$C$33)*AB53+(1-$C$34)*AC53+(1-$C$35)*AD53+$C$32*AE53+$C$33*AF53+$C$34*AG53+$C$35*AH53),0) -> 0 | D20: =SUM(AA48,AA52)*(1-$C$32)+SUM(AB48,AB52)*(1-$C$33)+SUM(AC48,AC52)*(1-$C$34)+SUM(AD48,AD52)*(1-$C$35)+SUM(AE48,AE52)*$C$32+SUM(AF48,AF52)*$C$33+SUM(AG48,AG52)*$C$34+SUM(AH48,AH52)*$C$35 -> 0 | E20: =(1-$C$32)*AA53+(1-$C$33)*AB53+(1-$C$34)*AC53+(1-$C$35)*AD53+$C$32*AE53+$C$33*AF53+$C$34*AG53+$C$35*AH53 -> 0 | F20: =(1-$C$32)*AA47+(1-$C$33)*AB47+(1-$C$34)*AC47+(1-$C$35)*AD47+$C$32*AE47+$C$33*AF47+$C$34*AG47+$C$35*AH47 -> 0 | G20: =SUM(AA48,AA49,AA52)*(1-$C$32)+SUM(AB48,AB49,AB52)*(1-$C$33)+SUM(AC48,AC49,AC52)*(1-$C$34)+SUM(AD48,AD49,AD52)*(1-$C$35)+SUM(AE48,AE49,AE52)*$C$32+SUM(AF48,AF49,AF52)*$C$33+SUM(AG48,AG49,AG52)*$C$34+SUM(AH48,AH49,AH52)*$C$35 -> 0 | I20: 7 | J20: 1 | K20: 1 | L20: 0.33 | M20: 0
B21: ='1. Business Financials'!N27 | C21: =IFERROR((C20+(1-$C$32)*AE47+(1-$C$33)*AF47+(1-$C$34)*AG47+(1-$C$35)*AH47+$C$32*AI47+$C$33*AJ47+$C$34*AK47+$C$35*AL47+(1-$C$32)*AE49+(1-$C$33)*AF49+(1-$C$34)*AG49+(1-$C$35)*AH49+$C$32*AI49+$C$33*AJ49+$C$34*AK49+$C$35*AL49)-((1-$C$32)*AE53+(1-$C$33)*AF53+(1-$C$34)*AG53+(1-$C$35)*AH53+$C$32*AI53+$C$33*AJ53+$C$34*AK53+$C$35*AL53),0) -> 0 | D21: =SUM(AE48,AE52)*(1-$C$32)+SUM(AF48,AF52)*(1-$C$33)+SUM(AG48,AG52)*(1-$C$34)+SUM(AH48,AH52)*(1-$C$35)+SUM(AI48,AI52)*$C$32+SUM(AJ48,AJ52)*$C$33+SUM(AK48,AK52)*$C$34+SUM(AL48,AL52)*$C$35 -> 0 | E21: =(1-$C$32)*AE53+(1-$C$33)*AF53+(1-$C$34)*AG53+(1-$C$35)*AH53+$C$32*AI53+$C$33*AJ53+$C$34*AK53+$C$35*AL53 -> 0 | F21: =(1-$C$32)*AE47+(1-$C$33)*AF47+(1-$C$34)*AG47+(1-$C$35)*AH47+$C$32*AI47+$C$33*AJ47+$C$34*AK47+$C$35*AL47 -> 0 | G21: =SUM(AE48,AE49,AE52)*(1-$C$32)+SUM(AF48,AF49,AF52)*(1-$C$33)+SUM(AG48,AG49,AG52)*(1-$C$34)+SUM(AH48,AH49,AH52)*(1-$C$35)+SUM(AI48,AI49,AI52)*$C$32+SUM(AJ48,AJ49,AJ52)*$C$33+SUM(AK48,AK49,AK52)*$C$34+SUM(AL48,AL49,AL52)*$C$35 -> 0 | I21: 8 | J21: 1 | K21: 1 | L21: 0.67 | M21: 0
B22: ='1. Business Financials'!O27 | C22: =IFERROR((C21+(1-$C$32)*AI47+(1-$C$33)*AJ47+(1-$C$34)*AK47+(1-$C$35)*AL47+$C$32*AM47+$C$33*AN47+$C$34*AO47+$C$35*OK47+(1-$C$32)*AI49+(1-$C$33)*AJ49+(1-$C$34)*AK49+(1-$C$35)*AL49+$C$32*AM49+$C$33*AN49+$C$34*AO49+$C$35*OK49)-((1-$C$32)*AI53+(1-$C$33)*AJ53+(1-$C$34)*AK53+(1-$C$35)*AL53+$C$32*AM53+$C$33*AN53+$C$34*AO53+$C$35*AP53),0) -> 0 | D22: =SUM(AI48,AI52)*(1-$C$32)+SUM(AJ48,AJ52)*(1-$C$33)+SUM(AK48,AK52)*(1-$C$34)+SUM(AL48,AL52)*(1-$C$35)+SUM(AM48,AM52)*$C$32+SUM(AN48,AN52)*$C$33+SUM(AO48,AO52)*$C$34+SUM(AP48,AP52)*$C$35 -> 0 | E22: =(1-$C$32)*AI53+(1-$C$33)*AJ53+(1-$C$34)*AK53+(1-$C$35)*AL53+$C$32*AM53+$C$33*AN53+$C$34*AO53+$C$35*AP53 -> 0 | F22: =(1-$C$32)*AI47+(1-$C$33)*AJ47+(1-$C$34)*AK47+(1-$C$35)*AL47+$C$32*AM47+$C$33*AN47+$C$34*AO47+$C$35*AP47 -> 0 | G22: =SUM(AI48,AI49,AI52)*(1-$C$32)+SUM(AJ48,AJ49,AJ52)*(1-$C$33)+SUM(AK48,AK49,AK52)*(1-$C$34)+SUM(AL48,AL49,AL52)*(1-$C$35)+SUM(AM48,AM49,AM52)*$C$32+SUM(AN48,AN49,AN52)*$C$33+SUM(AO48,AO49,AO52)*$C$34+SUM(AP48,AP49,AP52)*$C$35 -> 0 | I22: 9 | J22: 1 | K22: 1 | L22: 1 | M22: 0
I23: 10 | J23: 1 | K23: 1 | L23: 1 | M23: 0.33
B24: This table pulls the loan start date and subsequent financial year end from '1. Business Financials' tab. It calculates the number of months off-set between the two (row 25) and uses this to determine the loan exposure per financial quarter (from the months off-set table above). | I24: 11 | J24: 1 | K24: 1 | L24: 1 | M24: 0.67
B29: Loan start date | C29: ='1. Business Financials'!C21 -> 0
B30: Financial year-end | C30: =IFERROR('1. Business Financials'!C19,0) -> 0
B31: Off-set required | C31: =DATEDIF(C29,C30,"YM") -> 0 | D31: months
B32: Q1 exposure % | C32: =VLOOKUP($C$31,$I$13:$M$24,2,FALSE) -> 1
B33: Q2 exposure % | C33: =VLOOKUP($C$31,$I$13:$M$24,3,FALSE) -> 1
B34: Q3 exposure % | C34: =VLOOKUP($C$31,$I$13:$M$24,4,FALSE) -> 1
B35: Q4 exposure % | C35: =VLOOKUP($C$31,$I$13:$M$24,5,FALSE) -> 1
B37: The table below summarises the loan period in quarters, including availability, extension and repayment periods as calculated in tab '3. Repayment Calc Template'.
B38: Quarters | C38: 1 | D38: =C38+1 -> 2 | E38: =D38+1 -> 3 | F38: =E38+1 -> 4 | G38: =F38+1 -> 5 | H38: =G38+1 -> 6 | I38: =H38+1 -> 7 | J38: =I38+1 -> 8 | K38: =J38+1 -> 9 | ... AP38: =AO38+1 -> 40
B39: Loan | C39: ='3. Repayment Calc Template'!G11 -> 0 | D39: ='3. Repayment Calc Template'!G12 -> 0 | E39: ='3. Repayment Calc Template'!G13 -> 0 | F39: ='3. Repayment Calc Template'!G14 -> 0 | G39: ='3. Repayment Calc Template'!G15 -> 0 | H39: ='3. Repayment Calc Template'!G16 -> 0 | I39: ='3. Repayment Calc Template'!G17 -> 0 | J39: ='3. Repayment Calc Template'!G18 -> 0 | K39: ='3. Repayment Calc Template'!G19 -> 0 | L39: ='3. Repayment Calc Template'!G20 -> 0 | M39: ='3. Repayment Calc Template'!G21 -> 0 | N39: ='3. Repayment Calc Template'!G22 -> 0
B40: Interest paid | C40: =(IFERROR(HLOOKUP('4. Innovation Loans Calcs'!C38,'3. Repayment Calc Template'!$C$37:$N$39,2,FALSE),HLOOKUP('4. Innovation Loans Calcs'!C38,'3. Repayment Calc Template'!$C$46:$K$48,2,FALSE))) -> 0 | D40: =IFERROR(HLOOKUP('4. Innovation Loans Calcs'!D38,'3. Repayment Calc Template'!$C$37:$N$39,2,FALSE),HLOOKUP('4. Innovation Loans Calcs'!D38,'3. Repayment Calc Template'!$C$46:$K$48,2,FALSE)) -> #N/A | E40: =IFERROR(HLOOKUP('4. Innovation Loans Calcs'!E38,'3. Repayment Calc Template'!$C$37:$N$39,2,FALSE),HLOOKUP('4. Innovation Loans Calcs'!E38,'3. Repayment Calc Template'!$C$46:$K$48,2,FALSE)) -> #N/A | F40: =IFERROR(HLOOKUP('4. Innovation Loans Calcs'!F38,'3. Repayment Calc Template'!$C$37:$N$39,2,FALSE),HLOOKUP('4. Innovation Loans Calcs'!F38,'3. Repayment Calc Template'!$C$46:$K$48,2,FALSE)) -> #N/A | G40: =IFERROR(HLOOKUP('4. Innovation Loans Calcs'!G38,'3. Repayment Calc Template'!$C$37:$N$39,2,FALSE),HLOOKUP('4. Innovation Loans Calcs'!G38,'3. Repayment Calc Template'!$C$46:$K$48,2,FALSE)) -> #N/A | H40: =IFERROR(HLOOKUP('4. Innovation Loans Calcs'!H38,'3. Repayment Calc Template'!$C$37:$N$39,2,FALSE),HLOOKUP('4. Innovation Loans Calcs'!H38,'3. Repayment Calc Template'!$C$46:$K$48,2,FALSE)) -> #N/A | I40: =IFERROR(HLOOKUP('4. Innovation Loans Calcs'!I38,'3. Repayment Calc Template'!$C$37:$N$39,2,FALSE),HLOOKUP('4. Innovation Loans Calcs'!I38,'3. Repayment Calc Template'!$C$46:$K$48,2,FALSE)) -> #N/A | J40: =IFERROR(HLOOKUP('4. Innovation Loans Calcs'!J38,'3. Repayment Calc Template'!$C$37:$N$39,2,FALSE),HLOOKUP('4. Innovation Loans Calcs'!J38,'3. Repayment Calc Template'!$C$46:$K$48,2,FALSE)) -> #N/A | K40: =IFERROR(HLOOKUP('4. Innovation Loans Calcs'!K38,'3. Repayment Calc Template'!$C$37:$N$39,2,FALSE),HLOOKUP('4. Innovation Loans Calcs'!K38,'3. Repayment Calc Template'!$C$46:$K$48,2,FALSE)) -> #N/A | ... O40: =IFERROR(HLOOKUP('4. Innovation Loans Calcs'!O38,'3. Repayment Calc Template'!$C$37:$N$39,2,FALSE),HLOOKUP('4. Innovation Loans Calcs'!O38,'3. Repayment Calc Template'!$C$46:$K$48,2,FALSE)) -> #N/A | P40: =(IFERROR(HLOOKUP('4. Innovation Loans Calcs'!P38,'3. Repayment Calc Template'!$C$37:$N$39,2,FALSE),HLOOKUP('4. Innovation Loans Calcs'!P38,'3. Repayment Calc Template'!$C$46:$K$48,2,FALSE))) -> #N/A | Q40: =IFERROR(HLOOKUP('4. Innovation Loans Calcs'!Q38,'3. Repayment Calc Template'!$C$37:$N$39,2,FALSE),HLOOKUP('4. Innovation Loans Calcs'!Q38,'3. Repayment Calc Template'!$C$46:$K$48,2,FALSE)) -> #N/A | R40: =IFERROR(HLOOKUP('4. Innovation Loans Calcs'!R38,'3. Repayment Calc Template'!$C$37:$N$39,2,FALSE),HLOOKUP('4. Innovation Loans Calcs'!R38,'3. Repayment Calc Template'!$C$46:$K$48,2,FALSE)) -> #N/A | S40: =IFERROR(HLOOKUP('4. Innovation Loans Calcs'!S38,'3. Repayment Calc Template'!$C$37:$N$39,2,FALSE),HLOOKUP('4. Innovation Loans Calcs'!S38,'3. Repayment Calc Template'!$C$46:$K$48,2,FALSE)) -> #N/A | T40: =IFERROR(HLOOKUP('4. Innovation Loans Calcs'!T38,'3. Repayment Calc Template'!$C$37:$N$39,2,FALSE),HLOOKUP('4. Innovation Loans Calcs'!T38,'3. Repayment Calc Template'!$C$46:$K$48,2,FALSE)) -> #N/A | U40: =IFERROR(HLOOKUP('4. Innovation Loans Calcs'!U38,'3. Repayment Calc Template'!$C$37:$N$39,2,FALSE),HLOOKUP('4. Innovation Loans Calcs'!U38,'3. Repayment Calc Template'!$C$46:$K$48,2,FALSE)) -> #N/A | V40: =IFERROR(HLOOKUP('4. Innovation Loans Calcs'!V38,'3. Repayment Calc Template'!$C$37:$N$39,2,FALSE),HLOOKUP('4. Innovation Loans Calcs'!V38,'3. Repayment Calc Template'!$C$46:$K$48,2,FALSE)) -> #N/A | W40: =IFERROR(HLOOKUP('4. Innovation Loans Calcs'!W38,'3. Repayment Calc Template'!$C$37:$N$39,2,FALSE),HLOOKUP('4. Innovation Loans Calcs'!W38,'3. Repayment Calc Template'!$C$46:$K$48,2,FALSE)) -> #N/A | X40: =IFERROR(HLOOKUP('4. Innovation Loans Calcs'!X38,'3. Repayment Calc Template'!$C$37:$N$39,2,FALSE),HLOOKUP('4. Innovation Loans Calcs'!X38,'3. Repayment Calc Template'!$C$46:$K$48,2,FALSE)) -> #N/A | ... AP40: =IFERROR(HLOOKUP('4. Innovation Loans Calcs'!AP38,'3. Repayment Calc Template'!$C$37:$N$39,2,FALSE),HLOOKUP('4. Innovation Loans Calcs'!AP38,'3. Repayment Calc Template'!$C$46:$K$48,2,FALSE)) -> #N/A
B41: Interest deferred | C41: =IFERROR(HLOOKUP('4. Innovation Loans Calcs'!C38,'3. Repayment Calc Template'!$C$37:$N$39,3,FALSE),HLOOKUP('4. Innovation Loans Calcs'!C38,'3. Repayment Calc Template'!$C$46:$K$48,3,FALSE)) -> 0 | D41: =IFERROR(HLOOKUP('4. Innovation Loans Calcs'!D38,'3. Repayment Calc Template'!$C$37:$N$39,3,FALSE),HLOOKUP('4. Innovation Loans Calcs'!D38,'3. Repayment Calc Template'!$C$46:$K$48,3,FALSE)) -> #N/A | E41: =IFERROR(HLOOKUP('4. Innovation Loans Calcs'!E38,'3. Repayment Calc Template'!$C$37:$N$39,3,FALSE),HLOOKUP('4. Innovation Loans Calcs'!E38,'3. Repayment Calc Template'!$C$46:$K$48,3,FALSE)) -> #N/A | F41: =IFERROR(HLOOKUP('4. Innovation Loans Calcs'!F38,'3. Repayment Calc Template'!$C$37:$N$39,3,FALSE),HLOOKUP('4. Innovation Loans Calcs'!F38,'3. Repayment Calc Template'!$C$46:$K$48,3,FALSE)) -> #N/A | G41: =IFERROR(HLOOKUP('4. Innovation Loans Calcs'!G38,'3. Repayment Calc Template'!$C$37:$N$39,3,FALSE),HLOOKUP('4. Innovation Loans Calcs'!G38,'3. Repayment Calc Template'!$C$46:$K$48,3,FALSE)) -> #N/A | H41: =IFERROR(HLOOKUP('4. Innovation Loans Calcs'!H38,'3. Repayment Calc Template'!$C$37:$N$39,3,FALSE),HLOOKUP('4. Innovation Loans Calcs'!H38,'3. Repayment Calc Template'!$C$46:$K$48,3,FALSE)) -> #N/A | I41: =IFERROR(HLOOKUP('4. Innovation Loans Calcs'!I38,'3. Repayment Calc Template'!$C$37:$N$39,3,FALSE),HLOOKUP('4. Innovation Loans Calcs'!I38,'3. Repayment Calc Template'!$C$46:$K$48,3,FALSE)) -> #N/A | J41: =IFERROR(HLOOKUP('4. Innovation Loans Calcs'!J38,'3. Repayment Calc Template'!$C$37:$N$39,3,FALSE),HLOOKUP('4. Innovation Loans Calcs'!J38,'3. Repayment Calc Template'!$C$46:$K$48,3,FALSE)) -> #N/A | ... AP41: =IFERROR(HLOOKUP('4. Innovation Loans Calcs'!AP38,'3. Repayment Calc Template'!$C$37:$N$39,3,FALSE),HLOOKUP('4. Innovation Loans Calcs'!AP38,'3. Repayment Calc Template'!$C$46:$K$48,3,FALSE)) -> #N/A
B42: Fees (A&E) | C42: =IFERROR(HLOOKUP('4. Innovation Loans Calcs'!C38,'3. Repayment Calc Template'!$C$37:$N$41,4,FALSE),HLOOKUP('4. Innovation Loans Calcs'!C38,'3. Repayment Calc Template'!$C$46:$K$50,4,FALSE)) -> 0 | D42: =IFERROR(HLOOKUP('4. Innovation Loans Calcs'!D38,'3. Repayment Calc Template'!$C$37:$N$41,4,FALSE),HLOOKUP('4. Innovation Loans Calcs'!D38,'3. Repayment Calc Template'!$C$46:$K$50,4,FALSE)) -> #N/A | E42: =IFERROR(HLOOKUP('4. Innovation Loans Calcs'!E38,'3. Repayment Calc Template'!$C$37:$N$41,4,FALSE),HLOOKUP('4. Innovation Loans Calcs'!E38,'3. Repayment Calc Template'!$C$46:$K$50,4,FALSE)) -> #N/A | F42: =IFERROR(HLOOKUP('4. Innovation Loans Calcs'!F38,'3. Repayment Calc Template'!$C$37:$N$41,4,FALSE),HLOOKUP('4. Innovation Loans Calcs'!F38,'3. Repayment Calc Template'!$C$46:$K$50,4,FALSE)) -> #N/A | G42: =IFERROR(HLOOKUP('4. Innovation Loans Calcs'!G38,'3. Repayment Calc Template'!$C$37:$N$41,4,FALSE),HLOOKUP('4. Innovation Loans Calcs'!G38,'3. Repayment Calc Template'!$C$46:$K$50,4,FALSE)) -> #N/A | H42: =IFERROR(HLOOKUP('4. Innovation Loans Calcs'!H38,'3. Repayment Calc Template'!$C$37:$N$41,4,FALSE),HLOOKUP('4. Innovation Loans Calcs'!H38,'3. Repayment Calc Template'!$C$46:$K$50,4,FALSE)) -> #N/A | I42: =IFERROR(HLOOKUP('4. Innovation Loans Calcs'!I38,'3. Repayment Calc Template'!$C$37:$N$41,4,FALSE),HLOOKUP('4. Innovation Loans Calcs'!I38,'3. Repayment Calc Template'!$C$46:$K$50,4,FALSE)) -> #N/A | J42: =IFERROR(HLOOKUP('4. Innovation Loans Calcs'!J38,'3. Repayment Calc Template'!$C$37:$N$41,4,FALSE),HLOOKUP('4. Innovation Loans Calcs'!J38,'3. Repayment Calc Template'!$C$46:$K$50,4,FALSE)) -> #N/A | ... AP42: =IFERROR(HLOOKUP('4. Innovation Loans Calcs'!AP38,'3. Repayment Calc Template'!$C$37:$N$41,4,FALSE),HLOOKUP('4. Innovation Loans Calcs'!AP38,'3. Repayment Calc Template'!$C$46:$K$50,4,FALSE)) -> #N/A
B43: Fees (R) | C43: =HLOOKUP('4. Innovation Loans Calcs'!C38,'3. Repayment Calc Template'!$C$55:$V$58,4,FALSE) -> #N/A | D43: =HLOOKUP('4. Innovation Loans Calcs'!D38,'3. Repayment Calc Template'!$C$55:$V$58,4,FALSE) -> 0 | E43: =HLOOKUP('4. Innovation Loans Calcs'!E38,'3. Repayment Calc Template'!$C$55:$V$58,4,FALSE) -> #N/A | F43: =HLOOKUP('4. Innovation Loans Calcs'!F38,'3. Repayment Calc Template'!$C$55:$V$58,4,FALSE) -> #N/A | G43: =HLOOKUP('4. Innovation Loans Calcs'!G38,'3. Repayment Calc Template'!$C$55:$V$58,4,FALSE) -> #N/A | H43: =HLOOKUP('4. Innovation Loans Calcs'!H38,'3. Repayment Calc Template'!$C$55:$V$58,4,FALSE) -> #N/A | I43: =HLOOKUP('4. Innovation Loans Calcs'!I38,'3. Repayment Calc Template'!$C$55:$V$58,4,FALSE) -> #N/A | J43: =HLOOKUP('4. Innovation Loans Calcs'!J38,'3. Repayment Calc Template'!$C$55:$V$58,4,FALSE) -> #N/A | ... AP43: =HLOOKUP('4. Innovation Loans Calcs'!AP38,'3. Repayment Calc Template'!$C$55:$V$58,4,FALSE) -> #N/A
B44: Interest paid (repayment) | C44: =HLOOKUP('4. Innovation Loans Calcs'!C38,'3. Repayment Calc Template'!$C$55:$V$58,3,FALSE) -> #N/A | D44: =HLOOKUP('4. Innovation Loans Calcs'!D38,'3. Repayment Calc Template'!$C$55:$V$58,3,FALSE) -> 0 | E44: =HLOOKUP('4. Innovation Loans Calcs'!E38,'3. Repayment Calc Template'!$C$55:$V$58,3,FALSE) -> #N/A | F44: =HLOOKUP('4. Innovation Loans Calcs'!F38,'3. Repayment Calc Template'!$C$55:$V$58,3,FALSE) -> #N/A | G44: =HLOOKUP('4. Innovation Loans Calcs'!G38,'3. Repayment Calc Template'!$C$55:$V$58,3,FALSE) -> #N/A | H44: =HLOOKUP('4. Innovation Loans Calcs'!H38,'3. Repayment Calc Template'!$C$55:$V$58,3,FALSE) -> #N/A | I44: =HLOOKUP('4. Innovation Loans Calcs'!I38,'3. Repayment Calc Template'!$C$55:$V$58,3,FALSE) -> #N/A | J44: =HLOOKUP('4. Innovation Loans Calcs'!J38,'3. Repayment Calc Template'!$C$55:$V$58,3,FALSE) -> #N/A | ... AP44: =HLOOKUP('4. Innovation Loans Calcs'!AP38,'3. Repayment Calc Template'!$C$55:$V$58,3,FALSE) -> #N/A
B45: Capital repayment | C45: =HLOOKUP('4. Innovation Loans Calcs'!C38,'3. Repayment Calc Template'!$C$55:$V$58,2,FALSE) -> #N/A | D45: =HLOOKUP('4. Innovation Loans Calcs'!D38,'3. Repayment Calc Template'!$C$55:$V$58,2,FALSE) -> 0 | E45: =HLOOKUP('4. Innovation Loans Calcs'!E38,'3. Repayment Calc Template'!$C$55:$V$58,2,FALSE) -> #N/A | F45: =HLOOKUP('4. Innovation Loans Calcs'!F38,'3. Repayment Calc Template'!$C$55:$V$58,2,FALSE) -> #N/A | G45: =HLOOKUP('4. Innovation Loans Calcs'!G38,'3. Repayment Calc Template'!$C$55:$V$58,2,FALSE) -> #N/A | H45: =HLOOKUP('4. Innovation Loans Calcs'!H38,'3. Repayment Calc Template'!$C$55:$V$58,2,FALSE) -> #N/A | I45: =HLOOKUP('4. Innovation Loans Calcs'!I38,'3. Repayment Calc Template'!$C$55:$V$58,2,FALSE) -> #N/A | J45: =HLOOKUP('4. Innovation Loans Calcs'!J38,'3. Repayment Calc Template'!$C$55:$V$58,2,FALSE) -> #N/A | ... AP45: =HLOOKUP('4. Innovation Loans Calcs'!AP38,'3. Repayment Calc Template'!$C$55:$V$58,2,FALSE) -> #N/A
B47: Loan | C47: =IFERROR(C39,0) -> 0 | D47: =IFERROR(D39,0) -> 0 | E47: =IFERROR(E39,0) -> 0 | F47: =IFERROR(F39,0) -> 0 | G47: =IFERROR(G39,0) -> 0 | H47: =IFERROR(H39,0) -> 0 | I47: =IFERROR(I39,0) -> 0 | J47: =IFERROR(J39,0) -> 0 | ... AP47: =IFERROR(AP39,0) -> 0
B48: Interest paid | C48: =IFERROR(C40,0) -> 0 | D48: =IFERROR(D40,0) -> 0 | E48: =IFERROR(E40,0) -> 0 | F48: =IFERROR(F40,0) -> 0 | G48: =IFERROR(G40,0) -> 0 | H48: =IFERROR(H40,0) -> 0 | I48: =IFERROR(I40,0) -> 0 | J48: =IFERROR(J40,0) -> 0 | ... AP48: =IFERROR(AP40,0) -> 0
B49: Interest deferred | C49: =IFERROR(C41,0) -> 0 | D49: =IFERROR(D41,0) -> 0 | E49: =IFERROR(E41,0) -> 0 | F49: =IFERROR(F41,0) -> 0 | G49: =IFERROR(G41,0) -> 0 | H49: =IFERROR(H41,0) -> 0 | I49: =IFERROR(I41,0) -> 0 | J49: =IFERROR(J41,0) -> 0 | ... AP49: =IFERROR(AP41,0) -> 0
B50: Fees (A&E) | C50: =IFERROR(C42,0) -> 0 | D50: =IFERROR(D42,0) -> 0 | E50: =IFERROR(E42,0) -> 0 | F50: =IFERROR(F42,0) -> 0 | G50: =IFERROR(G42,0) -> 0 | H50: =IFERROR(H42,0) -> 0 | I50: =IFERROR(I42,0) -> 0 | J50: =IFERROR(J42,0) -> 0 | ... AP50: =IFERROR(AP42,0) -> 0
B51: Fees (R) | C51: =IFERROR(C43,0) -> 0 | D51: =IFERROR(D43,0) -> 0 | E51: =IFERROR(E43,0) -> 0 | F51: =IFERROR(F43,0) -> 0 | G51: =IFERROR(G43,0) -> 0 | H51: =IFERROR(H43,0) -> 0 | I51: =IFERROR(I43,0) -> 0 | J51: =IFERROR(J43,0) -> 0 | ... AP51: =IFERROR(AP43,0) -> 0
B52: Interest paid (repayment) | C52: =IFERROR(C44,0) -> 0 | D52: =IFERROR(D44,0) -> 0 | E52: =IFERROR(E44,0) -> 0 | F52: =IFERROR(F44,0) -> 0 | G52: =IFERROR(G44,0) -> 0 | H52: =IFERROR(H44,0) -> 0 | I52: =IFERROR(I44,0) -> 0 | J52: =IFERROR(J44,0) -> 0 | ... AP52: =IFERROR(AP44,0) -> 0
B53: Capital repayment | C53: =IFERROR(C45,0) -> 0 | D53: =IFERROR(D45,0) -> 0 | E53: =IFERROR(E45,0) -> 0 | F53: =IFERROR(F45,0) -> 0 | G53: =IFERROR(G45,0) -> 0 | H53: =IFERROR(H45,0) -> 0 | I53: =IFERROR(I45,0) -> 0 | J53: =IFERROR(J45,0) -> 0 | ... AP53: =IFERROR(AP45,0) -> 0
B54: Total payments | C54: =SUM(C48:C53) -> 0 | D54: =SUM(D48:D53) -> 0 | E54: =SUM(E48:E53) -> 0 | F54: =SUM(F48:F53) -> 0 | G54: =SUM(G48:G53) -> 0 | H54: =SUM(H48:H53) -> 0 | I54: =SUM(I48:I53) -> 0 | J54: =SUM(J48:J53) -> 0 | ... AP54: =SUM(AP48:AP53) -> 0

Sheet 5. Reference Rate Template
B2: Reference rate Calculator Template
B4: Instructions: This sheet is a tool to help you calculate the 'market' cost of the loan using a traditional structure, the reference rate for interest and typical fees. Note that the reference rate is assumed to be the highest rate that falls within our risk appetite. This tab will auto-populate based on your inputs in tab 3.
B7: Innovation Loan Request
B9: Eligible Project Costs | C9: ='3. Repayment Calc Template'!C9 -> 0
B10: Loan Amount | C10: ='3. Repayment Calc Template'!C10 -> 0 | F10: Anticipated Drawdowns | I10: Anticipated Principal Outstanding | L10: Fees | AD10: 1 | AE10: 3 Months
C11: Quarters | D11: Years | F11: Quarter 1 | G11: ='3. Repayment Calc Template'!G11 -> 0 | I11: Quarter 1 | J11: =G11 -> 0 | L11: Arrangement | M11: 0.03 | AD11: 2 | AE11: 6 Months
B12: Availability Period | C12: ='3. Repayment Calc Template'!C12 -> 0 | D12: =IFERROR(VLOOKUP(C12,AD:AE,2,FALSE),"") | F12: Quarter 2 | G12: ='3. Repayment Calc Template'!G12 -> 0 | I12: Quarter 2 | J12: =+J11+G12 -> 0 | L12: Monitoring | M12: 0.0075 | AD12: 3 | AE12: 9 Months
B13: Extension Period | C13: ='3. Repayment Calc Template'!C13 -> 0 | D13: =IFERROR(VLOOKUP(C13,AD:AE,2,FALSE),"") | F13: Quarter 3 | G13: ='3. Repayment Calc Template'!G13 -> 0 | I13: Quarter 3 | J13: =+J12+G13 -> 0 | L13: Interest | AD13: 4 | AE13: 1 Year
B14: Repayment Period | C14: ='3. Repayment Calc Template'!C14 -> 0 | D14: =IFERROR(VLOOKUP(C14,AD:AE,2,FALSE),"") | F14: Quarter 4 | G14: ='3. Repayment Calc Template'!G14 -> 0 | I14: Quarter 4 | J14: =+J13+G14 -> 0 | L14: Reference | M14: 0.1424 | N14: Assuming B- rating | AD14: 5 | AE14: 15 Months
B15: No. of repayment quarters | C15: =C14 -> 0 | D15: =IF(SUM(C12:C14)>28,"Total loan term exceeds 7 years","") | F15: Quarter 5 | G15: ='3. Repayment Calc Template'!G15 -> 0 | I15: Quarter 5 | J15: =+J14+G15 -> 0 | L15: Actual | M15: =M16+M17 -> 0.074 | AD15: 6 | AE15: 18 Months
F16: Quarter 6 | G16: ='3. Repayment Calc Template'!G16 -> 0 | I16: Quarter 6 | J16: =+J15+G16 -> 0 | L16: Current | M16: 0.037
F17: Quarter 7 | G17: ='3. Repayment Calc Template'!G17 -> 0 | I17: Quarter 7 | J17: =+J16+G17 -> 0 | L17: Deferred | M17: 0.037 | AD17: 7 | AE17: 21 Months
B18: Interest rate | C18: Quarterly % | D18: Qtly deferred % | F18: Quarter 8 | G18: ='3. Repayment Calc Template'!G18 -> 0 | I18: Quarter 8 | J18: =+J17+G18 -> 0 | AD18: 8 | AE18: 2 Years
B19: Availabilty Period | C19: =(M14*91.25/365) -> 0.0356 | D19: 0 | F19: Quarter 9 | G19: ='3. Repayment Calc Template'!G19 -> 0 | I19: Quarter 9 | J19: =+J18+G19 -> 0 | AD19: 9 | AE19: 27 Months
B20: Extension Period | C20: =(M14*91.25/365) -> 0.0356 | D20: 0 | F20: Quarter 10 | G20: ='3. Repayment Calc Template'!G20 -> 0 | I20: Quarter 10 | J20: =+J19+G20 -> 0 | AD20: 10 | AE20: 2.5 Years
B21: Repayment Period | C21: =(M14*91.25/365) -> 0.0356 | D21: 0 | F21: Quarter 11 | G21: ='3. Repayment Calc Template'!G21 -> 0 | I21: Quarter 11 | J21: =+J20+G21 -> 0 | AD21: 11 | AE21: 33 Months
F22: Quarter 12 | G22: ='3. Repayment Calc Template'!G22 -> 0 | I22: Quarter 12 | J22: =+J21+G22 -> 0 | AD22: 12 | AE22: 3 Years
B23: Total Interest (A & E & R periods) | C23: =SUM(C47:J48)+SUM(C38:N40)+SUM(C57:V57) -> 0 | AD23: 13 | AE23: 39 Months
B24: Interest paid (A & E periods) | C24: =SUM(C47:J47)+SUM(C38:N38) -> 0 | AD24: 14 | AE24: 3.5 Years
B25: Deferred interest (A & E periods) | C25: =SUM(C48:J48)+SUM(C39:N39) -> 0 | AD25: 15 | AE25: 45 Months
B26: Interest paid (R period) | C26: =SUM(C57:V57) -> 0
B27: Fees paid | C27: =SUM(C40:N40)+SUM(C49:J49)+SUM(C58:V58) -> 0
B28: Total Principal | C28: =SUM(G11:G22) -> 0
B29: Total amount borrowed | C29: =SUM(G11:G22)+C25 -> 0
B30: Total payments (principal/interest/fees) | C30: =SUM(C59:V59)+SUM(C47:J49)+SUM(C38:N40) -> 0
B31: Quarterly Payment (excl fees) | C31: =IFERROR(-PMT(M14*91.25/365,C14,C29,0),0) -> 0 | D31: =C31*12 -> 0
B33: Availability, Extension and Repayment Profiles
AD34: 16 | AE34: 4 Years
B35: Availability Period | AD35: 17 | AE35: 51 Months
C36: Quarter 1 | D36: Quarter 2 | E36: Quarter 3 | F36: Quarter 4 | G36: Quarter 5 | H36: Quarter 6 | I36: Quarter 7 | J36: Quarter 8 | K36: Quarter 9 | L36: Quarter 10 | M36: Quarter 11 | N36: Quarter 12 | AD36: 18 | AE36: 4.5 Years
C37: 1 | D37: =IF(C37=0,0,IF($C$12>C37,C37+1,0)) -> 0 | E37: =IF(D37=0,0,IF($C$12>D37,D37+1,0)) -> 0 | F37: =IF(E37=0,0,IF($C$12>E37,E37+1,0)) -> 0 | G37: =IF(F37=0,0,IF($C$12>F37,F37+1,0)) -> 0 | H37: =IF(G37=0,0,IF($C$12>G37,G37+1,0)) -> 0 | I37: =IF(H37=0,0,IF($C$12>H37,H37+1,0)) -> 0 | J37: =IF(I37=0,0,IF($C$12>I37,I37+1,0)) -> 0 | K37: =IF(J37=0,0,IF($C$12>J37,J37+1,0)) -> 0 | ... N37: =IF(M37=0,0,IF($C$12>M37,M37+1,0)) -> 0
B38: Interest paid (A & E periods) | C38: =IF($C12>=1,$G11*$C19,0) -> 0 | D38: =IF($C12>=2,SUM($G11:$G12)*$C19,0) -> 0 | E38: =IF($C12>=3,SUM($G11:$G13)*$C19,0) -> 0 | F38: =IF($C12>=4,SUM($G11:$G14)*$C19,0) -> 0 | G38: =IF($C12>=5,SUM($G11:$G15)*$C19,0) -> 0 | H38: =IF($C12>=6,SUM($G11:$G16)*$C19,0) -> 0 | I38: =IF($C12>=7,SUM($G11:$G17)*$C19,0) -> 0 | J38: =IF($C12>=8,SUM($G11:$G18)*$C19,0) -> 0 | K38: =IF($C12>=9,SUM($G11:$G19)*$C19,0) -> 0 | L38: =IF($C12>=10,SUM($G11:$G20)*$C19,0) -> 0 | M38: =IF($C12>=11,SUM($G11:$G21)*$C19,0) -> 0 | N38: =IF($C12>=12,SUM($G11:$G22)*$C19,0) -> 0 | AD38: 19 | AE38: 57 Months
B39: Deferred interest | C39: 0 | D39: 0 | E39: 0 | F39: 0 | G39: 0 | H39: 0 | I39: 0 | J39: 0 | K39: 0 | L39: 0 | M39: 0 | N39: 0 | AD39: 20 | AE39: 5 Years
B40: Fees | C40: =IF($C12>=1,((C10*M11)+($J11*$M12/4)),0) -> 0 | D40: =IF($C12>=2,(($J12*$M12/4)),0) -> 0 | E40: =IF($C12>=3,(($J13*$M12/4)),0) -> 0 | F40: =IF($C12>=4,(($J14*$M12/4)),0) -> 0 | G40: =IF($C12>=5,(($J15*$M12/4)),0) -> 0 | H40: =IF($C12>=6,(($J16*$M12/4)),0) -> 0 | I40: =IF($C12>=7,(($J17*$M12/4)),0) -> 0 | J40: =IF($C12>=8,(($J18*$M12/4)),0) -> 0 | K40: =IF($C12>=9,(($J19*$M12/4)),0) -> 0 | L40: =IF($C12>=10,(($J20*$M12/4)),0) -> 0 | M40: =IF($C12>=11,(($J21*$M12/4)),0) -> 0 | N40: =IF($C12>=12,(($J22*$M12/4)),0) -> 0
B41: Total | C41: =SUM(C38:C40) -> 0 | D41: =SUM(D38:D40) -> 0 | E41: =SUM(E38:E40) -> 0 | F41: =SUM(F38:F40) -> 0 | G41: =SUM(G38:G40) -> 0 | H41: =SUM(H38:H40) -> 0 | I41: =SUM(I38:I40) -> 0 | J41: =SUM(J38:J40) -> 0 | ... N41: =SUM(N38:N40) -> 0
B44: Extension Period
C45: Quarter 1 | D45: Quarter 2 | E45: Quarter 3 | F45: Quarter 4 | G45: Quarter 5 | H45: Quarter 6 | I45: Quarter 7 | J45: Quarter 8
C46: =IF(C13=0,0,MAX(C37:N37)+1) -> 0 | D46: =IF(C46=0,0,IF(($C$12+$C$13)>C46,C46+1,0)) -> 0 | E46: =IF(D46=0,0,IF(($C$12+$C$13)>D46,D46+1,0)) -> 0 | F46: =IF(E46=0,0,IF(($C$12+$C$13)>E46,E46+1,0)) -> 0 | G46: =IF(F46=0,0,IF(($C$12+$C$13)>F46,F46+1,0)) -> 0 | H46: =IF(G46=0,0,IF(($C$12+$C$13)>G46,G46+1,0)) -> 0 | I46: =IF(H46=0,0,IF(($C$12+$C$13)>H46,H46+1,0)) -> 0 | J46: =IF(I46=0,0,IF(($C$12+$C$13)>I46,I46+1,0)) -> 0
B47: Interest paid (A & E periods) | C47: =IF($C13>=1,SUM($G11:$G23)*$C19,0) -> 0 | D47: =IF($C13>=2,SUM($G11:$G23)*$C19,0) -> 0 | E47: =IF($C13>=3,SUM($G11:$G23)*$C19,0) -> 0 | F47: =IF($C13>=4,SUM($G11:$G23)*$C19,0) -> 0 | G47: =IF($C13>=5,SUM($G11:$G23)*$C19,0) -> 0 | H47: =IF($C13>=6,SUM($G11:$G23)*$C19,0) -> 0 | I47: =IF($C13>=7,SUM($G11:$G23)*$C19,0) -> 0 | J47: =IF($C13>=8,SUM($G11:$G23)*$C19,0) -> 0
B48: Deferred interest | C48: 0 | D48: 0 | E48: 0 | F48: 0 | G48: 0 | H48: 0 | I48: 0 | J48: 0
...

Sheet 6. Grant Equiv Template
B2: Grant Equivalent Calculator Template
B4: Instructions: This sheet is a tool to help you calculate the grant equivalent of a loan, based on the difference between the '5. Reference Rate Template' (showing the market cost) and the '3. Repayment Calc Template' (showing the actual cost) for the loan. It will help you to determine the gross grant equivalent of the loan for subsidy control puroposes. This tab will auto-populate based on your inputs in tab 3.
B7: Innovation Loan Request
B9: Eligible Project Costs | C9: ='3. Repayment Calc Template'!C9 -> 0
B10: Loan Amount | C10: ='3. Repayment Calc Template'!C10 -> 0 | F10: Anticipated Drawdowns | I10: Anticipated Principal Outstanding | L10: Fees | AD10: 1 | AE10: 3 Months
C11: Quarters | D11: Years | F11: Quarter 1 | G11: ='3. Repayment Calc Template'!G11 -> 0 | I11: Quarter 1 | J11: =G11 -> 0 | L11: Arrangement | M11: ='5. Reference Rate Template'!M11-'3. Repayment Calc Template'!M11 -> 0.03 | AD11: 2 | AE11: 6 Months
B12: Availability Period | C12: ='3. Repayment Calc Template'!C12 -> 0 | D12: =VLOOKUP(C12,AD:AE,2,FALSE) -> #N/A | F12: Quarter 2 | G12: ='3. Repayment Calc Template'!G12 -> 0 | I12: Quarter 2 | J12: =+J11+G12 -> 0 | L12: Monitoring | M12: ='5. Reference Rate Template'!M12-'3. Repayment Calc Template'!M12 -> 0.0075 | AD12: 3 | AE12: 9 Months
B13: Extension Period | C13: ='3. Repayment Calc Template'!C13 -> 0 | D13: =VLOOKUP(C13,AD:AE,2,FALSE) -> #N/A | F13: Quarter 3 | G13: ='3. Repayment Calc Template'!G13 -> 0 | I13: Quarter 3 | J13: =+J12+G13 -> 0 | L13: Interest | AD13: 4 | AE13: 1 Year
B14: Repayment Period | C14: ='3. Repayment Calc Template'!C14 -> 0 | D14: =VLOOKUP(C14,AD:AE,2,FALSE) -> #N/A | F14: Quarter 4 | G14: ='3. Repayment Calc Template'!G14 -> 0 | I14: Quarter 4 | J14: =+J13+G14 -> 0 | L14: Reference | M14: 0.1424 | N14: Assuming B- rating | AD14: 5 | AE14: 15 Months
B15: No. of repayment quarters | C15: =C14 -> 0 | D15: =IF(SUM(C12:C14)>28,"Total loan term exceeds 7 years","") | F15: Quarter 5 | G15: ='3. Repayment Calc Template'!G15 -> 0 | I15: Quarter 5 | J15: =+J14+G15 -> 0 | L15: Actual | M15: =M16+M17 -> 0.074 | AD15: 6 | AE15: 18 Months
F16: Quarter 6 | G16: ='3. Repayment Calc Template'!G16 -> 0 | I16: Quarter 6 | J16: =+J15+G16 -> 0 | L16: Current | M16: 0.037
F17: Quarter 7 | G17: ='3. Repayment Calc Template'!G17 -> 0 | I17: Quarter 7 | J17: =+J16+G17 -> 0 | L17: Deferred | M17: 0.037 | AD17: 7 | AE17: 21 Months
B18: Interest rate | C18: Quarterly % | D18: Qtly deferred % | F18: Quarter 8 | G18: ='3. Repayment Calc Template'!G18 -> 0 | I18: Quarter 8 | J18: =+J17+G18 -> 0 | AD18: 8 | AE18: 2 Years
B19: Availabilty Period | C19: ='5. Reference Rate Template'!C19-'3. Repayment Calc Template'!C19 -> 0.02635 | D19: ='5. Reference Rate Template'!D19-'3. Repayment Calc Template'!D19 -> -0.00925 | F19: Quarter 9 | G19: ='3. Repayment Calc Template'!G19 -> 0 | I19: Quarter 9 | J19: =+J18+G19 -> 0 | AD19: 9 | AE19: 27 Months
B20: Extension Period | C20: ='5. Reference Rate Template'!C20-'3. Repayment Calc Template'!C20 -> 0.02635 | D20: ='5. Reference Rate Template'!D20-'3. Repayment Calc Template'!D20 -> -0.00925 | F20: Quarter 10 | G20: ='3. Repayment Calc Template'!G20 -> 0 | I20: Quarter 10 | J20: =+J19+G20 -> 0 | AD20: 10 | AE20: 2.5 Years
B21: Repayment Period | C21: ='5. Reference Rate Template'!C21-'3. Repayment Calc Template'!C21 -> 0.0171 | D21: ='5. Reference Rate Template'!D21-'3. Repayment Calc Template'!D21 -> 0 | F21: Quarter 11 | G21: ='3. Repayment Calc Template'!G21 -> 0 | I21: Quarter 11 | J21: =+J20+G21 -> 0 | AD21: 11 | AE21: 33 Months
F22: Quarter 12 | G22: ='3. Repayment Calc Template'!G22 -> 0 | I22: Quarter 12 | J22: =+J21+G22 -> 0 | AD22: 12 | AE22: 3 Years
B23: Total Interest (A & E & R periods) | C23: ='5. Reference Rate Template'!C23-'3. Repayment Calc Template'!C23 -> 0 | AD23: 13 | AE23: 39 Months
B24: Interest paid (A & E periods) | C24: ='5. Reference Rate Template'!C24-'3. Repayment Calc Template'!C24 -> 0 | AD24: 14 | AE24: 3.5 Years
B25: Deferred interest (A & E periods) | C25: ='5. Reference Rate Template'!C25-'3. Repayment Calc Template'!C25 -> 0 | AD25: 15 | AE25: 45 Months
B26: Interest paid (R period) | C26: ='5. Reference Rate Template'!C26-'3. Repayment Calc Template'!C26 -> 0
B27: Fees paid | C27: ='5. Reference Rate Template'!C27-'3. Repayment Calc Template'!C27 -> 0
B28: Total Principal | C28: ='5. Reference Rate Template'!C28-'3. Repayment Calc Template'!C28 -> 0
B29: Total amount borrowed | C29: ='5. Reference Rate Template'!C29-'3. Repayment Calc Template'!C29 -> 0
B30: Total payments (principal/interest/fees) | C30: ='5. Reference Rate Template'!C30-'3. Repayment Calc Template'!C30 -> 0
B31: Quarterly Payment (excl fees) | C31: ='5. Reference Rate Template'!C31-'3. Repayment Calc Template'!C31 -> 0 | D31: =C31*12 -> 0
B33: Availability, Extension and Repayment Profiles
AD34: 16 | AE34: 4 Years
B35: Availability Period | AD35: 17 | AE35: 51 Months
C36: Quarter 1 | D36: Quarter 2 | E36: Quarter 3 | F36: Quarter 4 | G36: Quarter 5 | H36: Quarter 6 | I36: Quarter 7 | J36: Quarter 8 | K36: Quarter 9 | L36: Quarter 10 | M36: Quarter 11 | N36: Quarter 12 | AD36: 18 | AE36: 4.5 Years
B37: Interest paid (A & E periods) | C37: ='5. Reference Rate Template'!C38-'3. Repayment Calc Template'!C38 -> 0 | D37: ='5. Reference Rate Template'!D38-'3. Repayment Calc Template'!D38 -> 0 | E37: ='5. Reference Rate Template'!E38-'3. Repayment Calc Template'!E38 -> 0 | F37: ='5. Reference Rate Template'!F38-'3. Repayment Calc Template'!F38 -> 0 | G37: ='5. Reference Rate Template'!G38-'3. Repayment Calc Template'!G38 -> 0 | H37: ='5. Reference Rate Template'!H38-'3. Repayment Calc Template'!H38 -> 0 | I37: ='5. Reference Rate Template'!I38-'3. Repayment Calc Template'!I38 -> 0 | J37: ='5. Reference Rate Template'!J38-'3. Repayment Calc Template'!J38 -> 0 | ... N37: ='5. Reference Rate Template'!N38-'3. Repayment Calc Template'!N38 -> 0 | AD37: 19 | AE37: 57 Months
B38: Deferred interest | C38: ='5. Reference Rate Template'!C39-'3. Repayment Calc Template'!C39 -> 0 | D38: ='5. Reference Rate Template'!D39-'3. Repayment Calc Template'!D39 -> 0 | E38: ='5. Reference Rate Template'!E39-'3. Repayment Calc Template'!E39 -> 0 | F38: ='5. Reference Rate Template'!F39-'3. Repayment Calc Template'!F39 -> 0 | G38: ='5. Reference Rate Template'!G39-'3. Repayment Calc Template'!G39 -> 0 | H38: ='5. Reference Rate Template'!H39-'3. Repayment Calc Template'!H39 -> 0 | I38: ='5. Reference Rate Template'!I39-'3. Repayment Calc Template'!I39 -> 0 | J38: ='5. Reference Rate Template'!J39-'3. Repayment Calc Template'!J39 -> 0 | ... N38: ='5. Reference Rate Template'!N39-'3. Repayment Calc Template'!N39 -> 0 | AD38: 20 | AE38: 5 Years
